[2022-08-11 17:20:49,933] {taskinstance.py:1032} INFO - Dependencies all met for <TaskInstance: LocalIngestionDag.gzip scheduled__2022-01-02T06:00:00+00:00 [queued]>
[2022-08-11 17:20:49,971] {taskinstance.py:1032} INFO - Dependencies all met for <TaskInstance: LocalIngestionDag.gzip scheduled__2022-01-02T06:00:00+00:00 [queued]>
[2022-08-11 17:20:49,972] {taskinstance.py:1238} INFO - 
--------------------------------------------------------------------------------
[2022-08-11 17:20:49,973] {taskinstance.py:1239} INFO - Starting attempt 6 of 6
[2022-08-11 17:20:49,974] {taskinstance.py:1240} INFO - 
--------------------------------------------------------------------------------
[2022-08-11 17:20:50,014] {taskinstance.py:1259} INFO - Executing <Task(BashOperator): gzip> on 2022-01-02 06:00:00+00:00
[2022-08-11 17:20:50,021] {standard_task_runner.py:52} INFO - Started process 6076 to run task
[2022-08-11 17:20:50,028] {standard_task_runner.py:76} INFO - Running: ['***', 'tasks', 'run', 'LocalIngestionDag', 'gzip', 'scheduled__2022-01-02T06:00:00+00:00', '--job-id', '50', '--raw', '--subdir', 'DAGS_FOLDER/data_ingestion_local.py', '--cfg-path', '/tmp/tmp1bqbf91z', '--error-file', '/tmp/tmp_l40t8rd']
[2022-08-11 17:20:50,031] {standard_task_runner.py:77} INFO - Job 50: Subtask gzip
[2022-08-11 17:20:50,150] {logging_mixin.py:109} INFO - Running <TaskInstance: LocalIngestionDag.gzip scheduled__2022-01-02T06:00:00+00:00 [running]> on host cdc85d7e6248
[2022-08-11 17:20:50,292] {logging_mixin.py:109} WARNING - /home/***/.local/lib/python3.7/site-packages/***/utils/context.py:152 AirflowContextDeprecationWarning: Accessing 'execution_date' from the template is deprecated and will be removed in a future version. Please use 'data_interval_start' or 'logical_date' instead.
[2022-08-11 17:20:50,331] {taskinstance.py:1426} INFO - Exporting the following env vars:
AIRFLOW_CTX_DAG_OWNER=***
AIRFLOW_CTX_DAG_ID=LocalIngestionDag
AIRFLOW_CTX_TASK_ID=gzip
AIRFLOW_CTX_EXECUTION_DATE=2022-01-02T06:00:00+00:00
AIRFLOW_CTX_DAG_RUN_ID=scheduled__2022-01-02T06:00:00+00:00
[2022-08-11 17:20:50,336] {subprocess.py:62} INFO - Tmp dir root location: 
 /tmp
[2022-08-11 17:20:50,338] {subprocess.py:74} INFO - Running command: ['bash', '-c', 'gunzip /opt/***/output_2021_01.csv.gz']
[2022-08-11 17:20:50,349] {subprocess.py:85} INFO - Output:
[2022-08-11 17:20:50,429] {subprocess.py:89} INFO - 
[2022-08-11 17:20:50,433] {subprocess.py:89} INFO - gzip: /opt/***/output_2021_01.csv.gz: not in gzip format
[2022-08-11 17:20:50,436] {subprocess.py:93} INFO - Command exited with return code 1
[2022-08-11 17:20:50,480] {taskinstance.py:1700} ERROR - Task failed with exception
Traceback (most recent call last):
  File "/home/airflow/.local/lib/python3.7/site-packages/airflow/models/taskinstance.py", line 1329, in _run_raw_task
    self._execute_task_with_callbacks(context)
  File "/home/airflow/.local/lib/python3.7/site-packages/airflow/models/taskinstance.py", line 1455, in _execute_task_with_callbacks
    result = self._execute_task(context, self.task)
  File "/home/airflow/.local/lib/python3.7/site-packages/airflow/models/taskinstance.py", line 1511, in _execute_task
    result = execute_callable(context=context)
  File "/home/airflow/.local/lib/python3.7/site-packages/airflow/operators/bash.py", line 188, in execute
    f'Bash command failed. The command returned a non-zero exit code {result.exit_code}.'
airflow.exceptions.AirflowException: Bash command failed. The command returned a non-zero exit code 1.
[2022-08-11 17:20:50,515] {taskinstance.py:1277} INFO - Marking task as FAILED. dag_id=LocalIngestionDag, task_id=gzip, execution_date=20220102T060000, start_date=20220811T172049, end_date=20220811T172050
[2022-08-11 17:20:50,565] {standard_task_runner.py:92} ERROR - Failed to execute job 50 for task gzip
Traceback (most recent call last):
  File "/home/airflow/.local/lib/python3.7/site-packages/airflow/task/task_runner/standard_task_runner.py", line 85, in _start_by_fork
    args.func(args, dag=self.dag)
  File "/home/airflow/.local/lib/python3.7/site-packages/airflow/cli/cli_parser.py", line 48, in command
    return func(*args, **kwargs)
  File "/home/airflow/.local/lib/python3.7/site-packages/airflow/utils/cli.py", line 92, in wrapper
    return f(*args, **kwargs)
  File "/home/airflow/.local/lib/python3.7/site-packages/airflow/cli/commands/task_command.py", line 298, in task_run
    _run_task_by_selected_method(args, dag, ti)
  File "/home/airflow/.local/lib/python3.7/site-packages/airflow/cli/commands/task_command.py", line 107, in _run_task_by_selected_method
    _run_raw_task(args, ti)
  File "/home/airflow/.local/lib/python3.7/site-packages/airflow/cli/commands/task_command.py", line 184, in _run_raw_task
    error_file=args.error_file,
  File "/home/airflow/.local/lib/python3.7/site-packages/airflow/utils/session.py", line 70, in wrapper
    return func(*args, session=session, **kwargs)
  File "/home/airflow/.local/lib/python3.7/site-packages/airflow/models/taskinstance.py", line 1329, in _run_raw_task
    self._execute_task_with_callbacks(context)
  File "/home/airflow/.local/lib/python3.7/site-packages/airflow/models/taskinstance.py", line 1455, in _execute_task_with_callbacks
    result = self._execute_task(context, self.task)
  File "/home/airflow/.local/lib/python3.7/site-packages/airflow/models/taskinstance.py", line 1511, in _execute_task
    result = execute_callable(context=context)
  File "/home/airflow/.local/lib/python3.7/site-packages/airflow/operators/bash.py", line 188, in execute
    f'Bash command failed. The command returned a non-zero exit code {result.exit_code}.'
airflow.exceptions.AirflowException: Bash command failed. The command returned a non-zero exit code 1.
[2022-08-11 17:20:50,607] {local_task_job.py:154} INFO - Task exited with return code 1
[2022-08-11 17:20:50,716] {local_task_job.py:264} INFO - 0 downstream tasks scheduled from follow-on schedule check
