[2022-08-11 15:54:37,435] {taskinstance.py:1032} INFO - Dependencies all met for <TaskInstance: LocalIngestionDag.ingest scheduled__2022-01-02T06:00:00+00:00 [queued]>
[2022-08-11 15:54:37,472] {taskinstance.py:1032} INFO - Dependencies all met for <TaskInstance: LocalIngestionDag.ingest scheduled__2022-01-02T06:00:00+00:00 [queued]>
[2022-08-11 15:54:37,474] {taskinstance.py:1238} INFO - 
--------------------------------------------------------------------------------
[2022-08-11 15:54:37,475] {taskinstance.py:1239} INFO - Starting attempt 3 of 3
[2022-08-11 15:54:37,476] {taskinstance.py:1240} INFO - 
--------------------------------------------------------------------------------
[2022-08-11 15:54:37,516] {taskinstance.py:1259} INFO - Executing <Task(BashOperator): ingest> on 2022-01-02 06:00:00+00:00
[2022-08-11 15:54:37,522] {standard_task_runner.py:52} INFO - Started process 460 to run task
[2022-08-11 15:54:37,528] {standard_task_runner.py:76} INFO - Running: ['***', 'tasks', 'run', 'LocalIngestionDag', 'ingest', 'scheduled__2022-01-02T06:00:00+00:00', '--job-id', '27', '--raw', '--subdir', 'DAGS_FOLDER/data_ingestion_local.py', '--cfg-path', '/tmp/tmpw3iu2bdv', '--error-file', '/tmp/tmpwh1s4w5f']
[2022-08-11 15:54:37,531] {standard_task_runner.py:77} INFO - Job 27: Subtask ingest
[2022-08-11 15:54:37,659] {logging_mixin.py:109} INFO - Running <TaskInstance: LocalIngestionDag.ingest scheduled__2022-01-02T06:00:00+00:00 [running]> on host cdc85d7e6248
[2022-08-11 15:54:37,828] {taskinstance.py:1426} INFO - Exporting the following env vars:
AIRFLOW_CTX_DAG_OWNER=***
AIRFLOW_CTX_DAG_ID=LocalIngestionDag
AIRFLOW_CTX_TASK_ID=ingest
AIRFLOW_CTX_EXECUTION_DATE=2022-01-02T06:00:00+00:00
AIRFLOW_CTX_DAG_RUN_ID=scheduled__2022-01-02T06:00:00+00:00
[2022-08-11 15:54:37,834] {subprocess.py:62} INFO - Tmp dir root location: 
 /tmp
[2022-08-11 15:54:37,836] {subprocess.py:74} INFO - Running command: ['bash', '-c', 'cd /opt/*** && cat output.csv']
[2022-08-11 15:54:37,851] {subprocess.py:85} INFO - Output:
[2022-08-11 15:54:37,917] {subprocess.py:89} INFO - cat: output.csv: No such file or directory
[2022-08-11 15:54:37,920] {subprocess.py:93} INFO - Command exited with return code 1
[2022-08-11 15:54:37,953] {taskinstance.py:1700} ERROR - Task failed with exception
Traceback (most recent call last):
  File "/home/airflow/.local/lib/python3.7/site-packages/airflow/models/taskinstance.py", line 1329, in _run_raw_task
    self._execute_task_with_callbacks(context)
  File "/home/airflow/.local/lib/python3.7/site-packages/airflow/models/taskinstance.py", line 1455, in _execute_task_with_callbacks
    result = self._execute_task(context, self.task)
  File "/home/airflow/.local/lib/python3.7/site-packages/airflow/models/taskinstance.py", line 1511, in _execute_task
    result = execute_callable(context=context)
  File "/home/airflow/.local/lib/python3.7/site-packages/airflow/operators/bash.py", line 188, in execute
    f'Bash command failed. The command returned a non-zero exit code {result.exit_code}.'
airflow.exceptions.AirflowException: Bash command failed. The command returned a non-zero exit code 1.
[2022-08-11 15:54:37,998] {taskinstance.py:1277} INFO - Marking task as FAILED. dag_id=LocalIngestionDag, task_id=ingest, execution_date=20220102T060000, start_date=20220811T155437, end_date=20220811T155437
[2022-08-11 15:54:38,042] {standard_task_runner.py:92} ERROR - Failed to execute job 27 for task ingest
Traceback (most recent call last):
  File "/home/airflow/.local/lib/python3.7/site-packages/airflow/task/task_runner/standard_task_runner.py", line 85, in _start_by_fork
    args.func(args, dag=self.dag)
  File "/home/airflow/.local/lib/python3.7/site-packages/airflow/cli/cli_parser.py", line 48, in command
    return func(*args, **kwargs)
  File "/home/airflow/.local/lib/python3.7/site-packages/airflow/utils/cli.py", line 92, in wrapper
    return f(*args, **kwargs)
  File "/home/airflow/.local/lib/python3.7/site-packages/airflow/cli/commands/task_command.py", line 298, in task_run
    _run_task_by_selected_method(args, dag, ti)
  File "/home/airflow/.local/lib/python3.7/site-packages/airflow/cli/commands/task_command.py", line 107, in _run_task_by_selected_method
    _run_raw_task(args, ti)
  File "/home/airflow/.local/lib/python3.7/site-packages/airflow/cli/commands/task_command.py", line 184, in _run_raw_task
    error_file=args.error_file,
  File "/home/airflow/.local/lib/python3.7/site-packages/airflow/utils/session.py", line 70, in wrapper
    return func(*args, session=session, **kwargs)
  File "/home/airflow/.local/lib/python3.7/site-packages/airflow/models/taskinstance.py", line 1329, in _run_raw_task
    self._execute_task_with_callbacks(context)
  File "/home/airflow/.local/lib/python3.7/site-packages/airflow/models/taskinstance.py", line 1455, in _execute_task_with_callbacks
    result = self._execute_task(context, self.task)
  File "/home/airflow/.local/lib/python3.7/site-packages/airflow/models/taskinstance.py", line 1511, in _execute_task
    result = execute_callable(context=context)
  File "/home/airflow/.local/lib/python3.7/site-packages/airflow/operators/bash.py", line 188, in execute
    f'Bash command failed. The command returned a non-zero exit code {result.exit_code}.'
airflow.exceptions.AirflowException: Bash command failed. The command returned a non-zero exit code 1.
[2022-08-11 15:54:38,067] {local_task_job.py:154} INFO - Task exited with return code 1
[2022-08-11 15:54:38,172] {local_task_job.py:264} INFO - 0 downstream tasks scheduled from follow-on schedule check
