[2022-08-11 18:48:34,652] {taskinstance.py:1032} INFO - Dependencies all met for <TaskInstance: LocalIngestionDag.ingest scheduled__2022-03-02T06:00:00+00:00 [queued]>
[2022-08-11 18:48:34,697] {taskinstance.py:1032} INFO - Dependencies all met for <TaskInstance: LocalIngestionDag.ingest scheduled__2022-03-02T06:00:00+00:00 [queued]>
[2022-08-11 18:48:34,699] {taskinstance.py:1238} INFO - 
--------------------------------------------------------------------------------
[2022-08-11 18:48:34,701] {taskinstance.py:1239} INFO - Starting attempt 2 of 2
[2022-08-11 18:48:34,702] {taskinstance.py:1240} INFO - 
--------------------------------------------------------------------------------
[2022-08-11 18:48:34,752] {taskinstance.py:1259} INFO - Executing <Task(PythonOperator): ingest> on 2022-03-02 06:00:00+00:00
[2022-08-11 18:48:34,772] {standard_task_runner.py:52} INFO - Started process 2351 to run task
[2022-08-11 18:48:34,790] {standard_task_runner.py:76} INFO - Running: ['***', 'tasks', 'run', 'LocalIngestionDag', 'ingest', 'scheduled__2022-03-02T06:00:00+00:00', '--job-id', '68', '--raw', '--subdir', 'DAGS_FOLDER/data_ingestion_local.py', '--cfg-path', '/tmp/tmpe6i9vsk8', '--error-file', '/tmp/tmpcpfjtne2']
[2022-08-11 18:48:34,793] {standard_task_runner.py:77} INFO - Job 68: Subtask ingest
[2022-08-11 18:48:34,944] {logging_mixin.py:109} INFO - Running <TaskInstance: LocalIngestionDag.ingest scheduled__2022-03-02T06:00:00+00:00 [running]> on host 3b421e1efda7
[2022-08-11 18:48:35,113] {logging_mixin.py:109} WARNING - /home/***/.local/lib/python3.7/site-packages/***/utils/context.py:152 AirflowContextDeprecationWarning: Accessing 'execution_date' from the template is deprecated and will be removed in a future version. Please use 'data_interval_start' or 'logical_date' instead.
[2022-08-11 18:48:35,174] {taskinstance.py:1426} INFO - Exporting the following env vars:
AIRFLOW_CTX_DAG_OWNER=***
AIRFLOW_CTX_DAG_ID=LocalIngestionDag
AIRFLOW_CTX_TASK_ID=ingest
AIRFLOW_CTX_EXECUTION_DATE=2022-03-02T06:00:00+00:00
AIRFLOW_CTX_DAG_RUN_ID=scheduled__2022-03-02T06:00:00+00:00
[2022-08-11 18:48:35,178] {logging_mixin.py:109} INFO - yellow_taxi_2021_03 /opt/***/output_2021-03.csv.gz
[2022-08-11 18:48:35,197] {logging_mixin.py:109} INFO - connection established successfully, inserting data...
[2022-08-11 18:48:35,199] {taskinstance.py:1700} ERROR - Task failed with exception
Traceback (most recent call last):
  File "/home/airflow/.local/lib/python3.7/site-packages/airflow/models/taskinstance.py", line 1329, in _run_raw_task
    self._execute_task_with_callbacks(context)
  File "/home/airflow/.local/lib/python3.7/site-packages/airflow/models/taskinstance.py", line 1455, in _execute_task_with_callbacks
    result = self._execute_task(context, self.task)
  File "/home/airflow/.local/lib/python3.7/site-packages/airflow/models/taskinstance.py", line 1511, in _execute_task
    result = execute_callable(context=context)
  File "/home/airflow/.local/lib/python3.7/site-packages/airflow/operators/python.py", line 174, in execute
    return_value = self.execute_callable()
  File "/home/airflow/.local/lib/python3.7/site-packages/airflow/operators/python.py", line 185, in execute_callable
    return self.python_callable(*self.op_args, **self.op_kwargs)
  File "/opt/airflow/dags/ingest_to_pg.py", line 18, in ingest_callable
    t_start = time()
TypeError: 'module' object is not callable
[2022-08-11 18:48:35,250] {taskinstance.py:1277} INFO - Marking task as FAILED. dag_id=LocalIngestionDag, task_id=ingest, execution_date=20220302T060000, start_date=20220811T184834, end_date=20220811T184835
[2022-08-11 18:48:35,302] {standard_task_runner.py:92} ERROR - Failed to execute job 68 for task ingest
Traceback (most recent call last):
  File "/home/airflow/.local/lib/python3.7/site-packages/airflow/task/task_runner/standard_task_runner.py", line 85, in _start_by_fork
    args.func(args, dag=self.dag)
  File "/home/airflow/.local/lib/python3.7/site-packages/airflow/cli/cli_parser.py", line 48, in command
    return func(*args, **kwargs)
  File "/home/airflow/.local/lib/python3.7/site-packages/airflow/utils/cli.py", line 92, in wrapper
    return f(*args, **kwargs)
  File "/home/airflow/.local/lib/python3.7/site-packages/airflow/cli/commands/task_command.py", line 298, in task_run
    _run_task_by_selected_method(args, dag, ti)
  File "/home/airflow/.local/lib/python3.7/site-packages/airflow/cli/commands/task_command.py", line 107, in _run_task_by_selected_method
    _run_raw_task(args, ti)
  File "/home/airflow/.local/lib/python3.7/site-packages/airflow/cli/commands/task_command.py", line 184, in _run_raw_task
    error_file=args.error_file,
  File "/home/airflow/.local/lib/python3.7/site-packages/airflow/utils/session.py", line 70, in wrapper
    return func(*args, session=session, **kwargs)
  File "/home/airflow/.local/lib/python3.7/site-packages/airflow/models/taskinstance.py", line 1329, in _run_raw_task
    self._execute_task_with_callbacks(context)
  File "/home/airflow/.local/lib/python3.7/site-packages/airflow/models/taskinstance.py", line 1455, in _execute_task_with_callbacks
    result = self._execute_task(context, self.task)
  File "/home/airflow/.local/lib/python3.7/site-packages/airflow/models/taskinstance.py", line 1511, in _execute_task
    result = execute_callable(context=context)
  File "/home/airflow/.local/lib/python3.7/site-packages/airflow/operators/python.py", line 174, in execute
    return_value = self.execute_callable()
  File "/home/airflow/.local/lib/python3.7/site-packages/airflow/operators/python.py", line 185, in execute_callable
    return self.python_callable(*self.op_args, **self.op_kwargs)
  File "/opt/airflow/dags/ingest_to_pg.py", line 18, in ingest_callable
    t_start = time()
TypeError: 'module' object is not callable
[2022-08-11 18:48:35,327] {local_task_job.py:154} INFO - Task exited with return code 1
[2022-08-11 18:48:35,408] {local_task_job.py:264} INFO - 0 downstream tasks scheduled from follow-on schedule check
